<?xml version="1.0"?>
<robot name="simple_humanoid">
  <!-- This is a simple humanoid robot model for educational purposes -->
  <!-- It includes basic body parts to demonstrate URDF concepts -->

  <!-- Body/Torso -->
  <link name="torso">
    <inertial>
      <origin xyz="0 0 0.3" rpy="0 0 0"/>
      <mass value="10.0"/>
      <inertia ixx="0.4" ixy="0.0" ixz="0.0" iyy="0.4" iyz="0.0" izz="0.2"/>
    </inertial>

    <visual>
      <origin xyz="0 0 0.3" rpy="0 0 0"/>
      <geometry>
        <box size="0.3 0.3 0.6"/>
      </geometry>
      <material name="body_color">
        <color rgba="0.8 0.8 0.8 1.0"/>
      </material>
    </visual>

    <collision>
      <origin xyz="0 0 0.3" rpy="0 0 0"/>
      <geometry>
        <box size="0.3 0.3 0.6"/>
      </geometry>
    </collision>
  </link>

  <!-- Head -->
  <link name="head">
    <inertial>
      <origin xyz="0 0 0" rpy="0 0 0"/>
      <mass value="2.0"/>
      <inertia ixx="0.01" ixy="0.0" ixz="0.0" iyy="0.01" iyz="0.0" izz="0.01"/>
    </inertial>

    <visual>
      <origin xyz="0 0 0" rpy="0 0 0"/>
      <geometry>
        <sphere radius="0.15"/>
      </geometry>
      <material name="skin_color">
        <color rgba="1.0 0.8 0.6 1.0"/>
      </material>
    </visual>

    <collision>
      <origin xyz="0 0 0" rpy="0 0 0"/>
      <geometry>
        <sphere radius="0.15"/>
      </geometry>
    </collision>
  </link>

  <!-- Neck joint connecting head to torso -->
  <joint name="neck_joint" type="fixed">
    <parent link="torso"/>
    <child link="head"/>
    <origin xyz="0 0 0.6" rpy="0 0 0"/>
  </joint>

  <!-- Left Upper Arm -->
  <link name="left_upper_arm">
    <inertial>
      <origin xyz="0 0 -0.15" rpy="0 0 0"/>
      <mass value="1.0"/>
      <inertia ixx="0.01" ixy="0.0" ixz="0.0" iyy="0.01" iyz="0.0" izz="0.001"/>
    </inertial>

    <visual>
      <origin xyz="0 0 -0.15" rpy="0 0 0"/>
      <geometry>
        <cylinder radius="0.05" length="0.3"/>
      </geometry>
      <material name="arm_color">
        <color rgba="0.6 0.6 0.6 1.0"/>
      </material>
    </visual>

    <collision>
      <origin xyz="0 0 -0.15" rpy="0 0 0"/>
      <geometry>
        <cylinder radius="0.05" length="0.3"/>
      </geometry>
    </collision>
  </link>

  <!-- Left Shoulder Joint -->
  <joint name="left_shoulder_joint" type="revolute">
    <parent link="torso"/>
    <child link="left_upper_arm"/>
    <origin xyz="0.2 0 0.3" rpy="0 0 0"/>
    <axis xyz="0 1 0"/>
    <limit lower="-1.57" upper="1.57" effort="10.0" velocity="1.0"/>
  </joint>

  <!-- Left Lower Arm -->
  <link name="left_lower_arm">
    <inertial>
      <origin xyz="0 0 -0.1" rpy="0 0 0"/>
      <mass value="0.8"/>
      <inertia ixx="0.008" ixy="0.0" ixz="0.0" iyy="0.008" iyz="0.0" izz="0.001"/>
    </inertial>

    <visual>
      <origin xyz="0 0 -0.1" rpy="0 0 0"/>
      <geometry>
        <cylinder radius="0.04" length="0.2"/>
      </geometry>
      <material name="arm_color">
        <color rgba="0.6 0.6 0.6 1.0"/>
      </material>
    </visual>

    <collision>
      <origin xyz="0 0 -0.1" rpy="0 0 0"/>
      <geometry>
        <cylinder radius="0.04" length="0.2"/>
      </geometry>
    </collision>
  </link>

  <!-- Left Elbow Joint -->
  <joint name="left_elbow_joint" type="revolute">
    <parent link="left_upper_arm"/>
    <child link="left_lower_arm"/>
    <origin xyz="0 0 -0.3" rpy="0 0 0"/>
    <axis xyz="0 1 0"/>
    <limit lower="0" upper="2.36" effort="8.0" velocity="1.0"/>
  </joint>

  <!-- Right Upper Arm -->
  <link name="right_upper_arm">
    <inertial>
      <origin xyz="0 0 -0.15" rpy="0 0 0"/>
      <mass value="1.0"/>
      <inertia ixx="0.01" ixy="0.0" ixz="0.0" iyy="0.01" iyz="0.0" izz="0.001"/>
    </inertial>

    <visual>
      <origin xyz="0 0 -0.15" rpy="0 0 0"/>
      <geometry>
        <cylinder radius="0.05" length="0.3"/>
      </geometry>
      <material name="arm_color">
        <color rgba="0.6 0.6 0.6 1.0"/>
      </material>
    </visual>

    <collision>
      <origin xyz="0 0 -0.15" rpy="0 0 0"/>
      <geometry>
        <cylinder radius="0.05" length="0.3"/>
      </geometry>
    </collision>
  </link>

  <!-- Right Shoulder Joint -->
  <joint name="right_shoulder_joint" type="revolute">
    <parent link="torso"/>
    <child link="right_upper_arm"/>
    <origin xyz="-0.2 0 0.3" rpy="0 0 0"/>
    <axis xyz="0 1 0"/>
    <limit lower="-1.57" upper="1.57" effort="10.0" velocity="1.0"/>
  </joint>

  <!-- Right Lower Arm -->
  <link name="right_lower_arm">
    <inertial>
      <origin xyz="0 0 -0.1" rpy="0 0 0"/>
      <mass value="0.8"/>
      <inertia ixx="0.008" ixy="0.0" ixz="0.0" iyy="0.008" iyz="0.0" izz="0.001"/>
    </inertial>

    <visual>
      <origin xyz="0 0 -0.1" rpy="0 0 0"/>
      <geometry>
        <cylinder radius="0.04" length="0.2"/>
      </geometry>
      <material name="arm_color">
        <color rgba="0.6 0.6 0.6 1.0"/>
      </material>
    </visual>

    <collision>
      <origin xyz="0 0 -0.1" rpy="0 0 0"/>
      <geometry>
        <cylinder radius="0.04" length="0.2"/>
      </geometry>
    </collision>
  </link>

  <!-- Right Elbow Joint -->
  <joint name="right_elbow_joint" type="revolute">
    <parent link="right_upper_arm"/>
    <child link="right_lower_arm"/>
    <origin xyz="0 0 -0.3" rpy="0 0 0"/>
    <axis xyz="0 1 0"/>
    <limit lower="0" upper="2.36" effort="8.0" velocity="1.0"/>
  </joint>

  <!-- Left Thigh (Upper Leg) -->
  <link name="left_thigh">
    <inertial>
      <origin xyz="0 0 -0.2" rpy="0 0 0"/>
      <mass value="2.0"/>
      <inertia ixx="0.02" ixy="0.0" ixz="0.0" iyy="0.02" iyz="0.0" izz="0.002"/>
    </inertial>

    <visual>
      <origin xyz="0 0 -0.2" rpy="0 0 0"/>
      <geometry>
        <cylinder radius="0.07" length="0.4"/>
      </geometry>
      <material name="leg_color">
        <color rgba="0.4 0.4 0.4 1.0"/>
      </material>
    </visual>

    <collision>
      <origin xyz="0 0 -0.2" rpy="0 0 0"/>
      <geometry>
        <cylinder radius="0.07" length="0.4"/>
      </geometry>
    </collision>
  </link>

  <!-- Left Hip Joint -->
  <joint name="left_hip_joint" type="revolute">
    <parent link="torso"/>
    <child link="left_thigh"/>
    <origin xyz="0.1 0 0" rpy="0 0 0"/>
    <axis xyz="0 1 0"/>
    <limit lower="-0.79" upper="0.79" effort="20.0" velocity="1.0"/>
  </joint>

  <!-- Left Shin (Lower Leg) -->
  <link name="left_shin">
    <inertial>
      <origin xyz="0 0 -0.2" rpy="0 0 0"/>
      <mass value="1.5"/>
      <inertia ixx="0.015" ixy="0.0" ixz="0.0" iyy="0.015" iyz="0.0" izz="0.0015"/>
    </inertial>

    <visual>
      <origin xyz="0 0 -0.2" rpy="0 0 0"/>
      <geometry>
        <cylinder radius="0.06" length="0.4"/>
      </geometry>
      <material name="leg_color">
        <color rgba="0.4 0.4 0.4 1.0"/>
      </material>
    </visual>

    <collision>
      <origin xyz="0 0 -0.2" rpy="0 0 0"/>
      <geometry>
        <cylinder radius="0.06" length="0.4"/>
      </geometry>
    </collision>
  </link>

  <!-- Left Knee Joint -->
  <joint name="left_knee_joint" type="revolute">
    <parent link="left_thigh"/>
    <child link="left_shin"/>
    <origin xyz="0 0 -0.4" rpy="0 0 0"/>
    <axis xyz="0 1 0"/>
    <limit lower="0" upper="2.36" effort="20.0" velocity="1.0"/>
  </joint>

  <!-- Left Foot -->
  <link name="left_foot">
    <inertial>
      <origin xyz="0.05 0 0" rpy="0 0 0"/>
      <mass value="0.5"/>
      <inertia ixx="0.001" ixy="0.0" ixz="0.0" iyy="0.001" iyz="0.0" izz="0.001"/>
    </inertial>

    <visual>
      <origin xyz="0.05 0 0" rpy="0 0 0"/>
      <geometry>
        <box size="0.15 0.1 0.05"/>
      </geometry>
      <material name="foot_color">
        <color rgba="0.2 0.2 0.2 1.0"/>
      </material>
    </visual>

    <collision>
      <origin xyz="0.05 0 0" rpy="0 0 0"/>
      <geometry>
        <box size="0.15 0.1 0.05"/>
      </geometry>
    </collision>
  </link>

  <!-- Left Ankle Joint -->
  <joint name="left_ankle_joint" type="revolute">
    <parent link="left_shin"/>
    <child link="left_foot"/>
    <origin xyz="0 0 -0.4" rpy="0 0 0"/>
    <axis xyz="1 0 0"/>
    <limit lower="-0.79" upper="0.79" effort="10.0" velocity="1.0"/>
  </joint>

  <!-- Right Thigh (Upper Leg) -->
  <link name="right_thigh">
    <inertial>
      <origin xyz="0 0 -0.2" rpy="0 0 0"/>
      <mass value="2.0"/>
      <inertia ixx="0.02" ixy="0.0" ixz="0.0" iyy="0.02" iyz="0.0" izz="0.002"/>
    </inertial>

    <visual>
      <origin xyz="0 0 -0.2" rpy="0 0 0"/>
      <geometry>
        <cylinder radius="0.07" length="0.4"/>
      </geometry>
      <material name="leg_color">
        <color rgba="0.4 0.4 0.4 1.0"/>
      </material>
    </visual>

    <collision>
      <origin xyz="0 0 -0.2" rpy="0 0 0"/>
      <geometry>
        <cylinder radius="0.07" length="0.4"/>
      </geometry>
    </collision>
  </link>

  <!-- Right Hip Joint -->
  <joint name="right_hip_joint" type="revolute">
    <parent link="torso"/>
    <child link="right_thigh"/>
    <origin xyz="-0.1 0 0" rpy="0 0 0"/>
    <axis xyz="0 1 0"/>
    <limit lower="-0.79" upper="0.79" effort="20.0" velocity="1.0"/>
  </joint>

  <!-- Right Shin (Lower Leg) -->
  <link name="right_shin">
    <inertial>
      <origin xyz="0 0 -0.2" rpy="0 0 0"/>
      <mass value="1.5"/>
      <inertia ixx="0.015" ixy="0.0" ixz="0.0" iyy="0.015" iyz="0.0" izz="0.0015"/>
    </inertial>

    <visual>
      <origin xyz="0 0 -0.2" rpy="0 0 0"/>
      <geometry>
        <cylinder radius="0.06" length="0.4"/>
      </geometry>
      <material name="leg_color">
        <color rgba="0.4 0.4 0.4 1.0"/>
      </material>
    </visual>

    <collision>
      <origin xyz="0 0 -0.2" rpy="0 0 0"/>
      <geometry>
        <cylinder radius="0.06" length="0.4"/>
      </geometry>
    </collision>
  </link>

  <!-- Right Knee Joint -->
  <joint name="right_knee_joint" type="revolute">
    <parent link="right_thigh"/>
    <child link="right_shin"/>
    <origin xyz="0 0 -0.4" rpy="0 0 0"/>
    <axis xyz="0 1 0"/>
    <limit lower="0" upper="2.36" effort="20.0" velocity="1.0"/>
  </joint>

  <!-- Right Foot -->
  <link name="right_foot">
    <inertial>
      <origin xyz="0.05 0 0" rpy="0 0 0"/>
      <mass value="0.5"/>
      <inertia ixx="0.001" ixy="0.0" ixz="0.0" iyy="0.001" iyz="0.0" izz="0.001"/>
    </inertial>

    <visual>
      <origin xyz="0.05 0 0" rpy="0 0 0"/>
      <geometry>
        <box size="0.15 0.1 0.05"/>
      </geometry>
      <material name="foot_color">
        <color rgba="0.2 0.2 0.2 1.0"/>
      </material>
    </visual>

    <collision>
      <origin xyz="0.05 0 0" rpy="0 0 0"/>
      <geometry>
        <box size="0.15 0.1 0.05"/>
      </geometry>
    </collision>
  </link>

  <!-- Right Ankle Joint -->
  <joint name="right_ankle_joint" type="revolute">
    <parent link="right_shin"/>
    <child link="right_foot"/>
    <origin xyz="0 0 -0.4" rpy="0 0 0"/>
    <axis xyz="1 0 0"/>
    <limit lower="-0.79" upper="0.79" effort="10.0" velocity="1.0"/>
  </joint>

  <!-- Gazebo-specific elements for simulation -->
  <gazebo reference="torso">
    <material>Gazebo/Gray</material>
  </gazebo>

  <gazebo reference="head">
    <material>Gazebo/Yellow</material>
  </gazebo>

  <gazebo>
    <plugin name="joint_state_publisher" filename="libgazebo_ros_joint_state_publisher.so">
      <joint_name>left_shoulder_joint</joint_name>
      <joint_name>right_shoulder_joint</joint_name>
      <joint_name>left_elbow_joint</joint_name>
      <joint_name>right_elbow_joint</joint_name>
      <joint_name>left_hip_joint</joint_name>
      <joint_name>right_hip_joint</joint_name>
      <joint_name>left_knee_joint</joint_name>
      <joint_name>right_knee_joint</joint_name>
      <joint_name>left_ankle_joint</joint_name>
      <joint_name>right_ankle_joint</joint_name>
    </plugin>
  </gazebo>
</robot>